<?xml version="1.0"?>

<robot 
    name="simple_robot" 
    xmlns:xacro="http://www.ros.org/wiki/xacro">

    <xacro:property
        name="controllers_file"
        value="$(find robot_description)/config/controllers.yaml"/>

    <link name="base_footprint"/>

    <link name="base_link">
        <visual>
            <origin xyz="0 0 0" 
                    rpy="0 0 0"/>

            <geometry>
                <box size="0.4 0.3 0.2"/>
            </geometry>
        </visual>

        <collision>
            <origin xyz="0 0 0"
                    rpy="0 0 0"/>
            
            <geometry>
                <box size="0.4 0.3 0.2"/>
            </geometry>
        </collision>

        <inertial>
            <origin xyz="0 0 0"
                    rpy="0 0 0"/>
            <mass value="1.0"/>
            <inertia
                ixx="0.0108" ixy="0.0" ixz="0.0"
                iyy="0.0167" iyz="0.0"
                izz="0.0208"/>
        </inertial>
    </link>

    <joint name="base_footprint_to_base_link" type="fixed">
        <parent link="base_footprint"/>
        <child link="base_link"/>
        <origin xyz="0 0 0.2"
                rpy="0 0 0"/>
    </joint>

    <xacro:include filename="$(find robot_description)/urdf/camera.xacro"/>

    <xacro:include filename="$(find robot_description)/urdf/gazebo_sensors.xacro"/>
    <link name="left_wheel_link">
        <visual>
            <origin xyz="0 0 0"
                    rpy="1.5708 0 0"/>
            <geometry>
                <cylinder radius="0.05" length="0.03"/>
            </geometry>
            <material name="black">
                <color rgba="0.1 0.1 0.1 1.0"/>
            </material>
        </visual>

        <collision>
            <origin xyz="0 0 0"
                    rpy="1.5708 0 0"/>
            
            <geometry>
                <cylinder radius="0.05" length="0.03"/>
            </geometry>
        </collision>

        <inertial>
            <origin xyz="0 0 0"
                    rpy="0 0 0"/>
            <mass value="0.1"/>
            <inertia
                ixx="0.000083" ixy="0.0" ixz="0.0"
                iyy="0.000083" iyz="0.0"
                izz="0.000125"/>
        </inertial>
    </link>

    <joint name="base_link_to_left_wheel_link"
            type="continuous">
        <parent link="base_link"/>
        <child link="left_wheel_link"/>
        <origin xyz="0 0.15 -0.15"
                rpy="0 0 0"/>
        <axis xyz="0 1 0"/>
    </joint>

    <link name="right_wheel_link">
        <visual>
            <origin xyz="0 0 0"
                    rpy="1.5708 0 0"/>
            <geometry>
                <cylinder radius="0.05" length="0.03"/>
            </geometry>
            <material name="black">
                <color rgba="0.1 0.1 0.1 1.0"/>
            </material>
        </visual>

        <collision>
            <origin xyz="0 0 0"
                    rpy="1.5708 0 0"/>
            
            <geometry>
                <cylinder radius="0.05" length="0.03"/>
            </geometry>
        </collision>

        <inertial>
            <origin xyz="0 0 0"
                    rpy="0 0 0"/>
            <mass value="0.1"/>
            <inertia
                ixx="0.000083" ixy="0.0" ixz="0.0"
                iyy="0.000083" iyz="0.0"
                izz="0.000125"/>
        </inertial>
    </link>

    <joint name="base_link_to_right_wheel_link"
            type="continuous">
        <parent link="base_link"/>
        <child link="right_wheel_link"/>
        <origin xyz="0 -0.15 -0.15"
                rpy="0 0 0"/>
        <axis xyz="0 1 0"/>
    </joint>

    <link name="caster_link">
        <visual>
            <origin xyz="0 0 0" rpy="0 0 0"/>
            <geometry>
                <sphere radius="0.05"/>
            </geometry>
        </visual>

        <collision>
            <origin xyz="0 0 0" rpy="0 0 0"/>
            <geometry>
                <sphere radius="0.05"/>
            </geometry>
        </collision>

        <inertial>
            <origin xyz="0 0 0" rpy="0 0 0"/>
            <mass value="0.05"/>
            <inertia
                ixx="0.0000125" ixy="0.0" ixz="0.0"
                iyy="0.0000125" iyz="0.0"
                izz="0.0000125"/>
        </inertial>
    </link>

    <joint name="base_link_to_caster_link" type="fixed">
        <parent link="base_link"/>
        <child link="caster_link"/>
        <origin xyz="-0.15 0 -0.15" rpy="0 0 0"/>
    </joint>

    <ros2_control
        name="GazeboSystem"
        type="system">
        <hardware>
            <plugin>gz_ros2_control/GazeboSimSystem</plugin>
        </hardware>

        <joint name="base_link_to_left_wheel_link">
            <command_interface name="velocity"/>
            <state_interface name="position"/>
            <state_interface name="velocity"/>
        </joint>

        <joint name="base_link_to_right_wheel_link">
            <command_interface name="velocity"/>
            <state_interface name="position"/>
            <state_interface name="velocity"/>
        </joint>
    </ros2_control>

    <gazebo>
        <plugin filename="gz_ros2_control-system"
                name="gz_ros2_control::GazeboSimROS2ControlPlugin">
            <parameters>/home/cheng/ros_ws/controllers.yaml</parameters>
        </plugin>
    </gazebo>
</robot>